2019-07-22 16:46:38,632 ERROR: Exception on / [GET] [in c:\users\samuel\microblog4\venv\lib\site-packages\flask\app.py:1761]
Traceback (most recent call last):
  File "c:\users\samuel\microblog4\venv\lib\site-packages\sqlalchemy\ext\declarative\clsregistry.py", line 294, in __call__
    x = eval(self.arg, globals(), self._dict)
  File "<string>", line 1, in <module>
NameError: name 'User' is not defined

During handling of the above exception, another exception occurred:

Traceback (most recent call last):
  File "c:\users\samuel\microblog4\venv\lib\site-packages\flask\app.py", line 2292, in wsgi_app
    response = self.full_dispatch_request()
  File "c:\users\samuel\microblog4\venv\lib\site-packages\flask\app.py", line 1815, in full_dispatch_request
    rv = self.handle_user_exception(e)
  File "c:\users\samuel\microblog4\venv\lib\site-packages\flask\app.py", line 1718, in handle_user_exception
    reraise(exc_type, exc_value, tb)
  File "c:\users\samuel\microblog4\venv\lib\site-packages\flask\_compat.py", line 35, in reraise
    raise value
  File "c:\users\samuel\microblog4\venv\lib\site-packages\flask\app.py", line 1811, in full_dispatch_request
    rv = self.preprocess_request()
  File "c:\users\samuel\microblog4\venv\lib\site-packages\flask\app.py", line 2087, in preprocess_request
    rv = func()
  File "C:\Users\Samuel\microblog4\app\routes.py", line 14, in before_request
    if current_user.is_authenticated:
  File "c:\users\samuel\microblog4\venv\lib\site-packages\werkzeug\local.py", line 348, in __getattr__
    return getattr(self._get_current_object(), name)
  File "c:\users\samuel\microblog4\venv\lib\site-packages\werkzeug\local.py", line 307, in _get_current_object
    return self.__local()
  File "c:\users\samuel\microblog4\venv\lib\site-packages\flask_login\utils.py", line 26, in <lambda>
    current_user = LocalProxy(lambda: _get_user())
  File "c:\users\samuel\microblog4\venv\lib\site-packages\flask_login\utils.py", line 335, in _get_user
    current_app.login_manager._load_user()
  File "c:\users\samuel\microblog4\venv\lib\site-packages\flask_login\login_manager.py", line 359, in _load_user
    return self.reload_user()
  File "c:\users\samuel\microblog4\venv\lib\site-packages\flask_login\login_manager.py", line 321, in reload_user
    user = self.user_callback(user_id)
  File "C:\Users\Samuel\microblog4\app\models.py", line 81, in load_user
    return Users.query.get(int(id))
  File "c:\users\samuel\microblog4\venv\lib\site-packages\flask_sqlalchemy\__init__.py", line 512, in __get__
    mapper = orm.class_mapper(type)
  File "c:\users\samuel\microblog4\venv\lib\site-packages\sqlalchemy\orm\base.py", line 441, in class_mapper
    mapper = _inspect_mapped_class(class_, configure=configure)
  File "c:\users\samuel\microblog4\venv\lib\site-packages\sqlalchemy\orm\base.py", line 420, in _inspect_mapped_class
    mapper._configure_all()
  File "c:\users\samuel\microblog4\venv\lib\site-packages\sqlalchemy\orm\mapper.py", line 1337, in _configure_all
    configure_mappers()
  File "c:\users\samuel\microblog4\venv\lib\site-packages\sqlalchemy\orm\mapper.py", line 3229, in configure_mappers
    mapper._post_configure_properties()
  File "c:\users\samuel\microblog4\venv\lib\site-packages\sqlalchemy\orm\mapper.py", line 1947, in _post_configure_properties
    prop.init()
  File "c:\users\samuel\microblog4\venv\lib\site-packages\sqlalchemy\orm\interfaces.py", line 196, in init
    self.do_init()
  File "c:\users\samuel\microblog4\venv\lib\site-packages\sqlalchemy\orm\relationships.py", line 1853, in do_init
    self._process_dependent_arguments()
  File "c:\users\samuel\microblog4\venv\lib\site-packages\sqlalchemy\orm\relationships.py", line 1915, in _process_dependent_arguments
    self.target = self.entity.persist_selectable
  File "c:\users\samuel\microblog4\venv\lib\site-packages\sqlalchemy\util\langhelpers.py", line 855, in __get__
    obj.__dict__[self.__name__] = result = self.fget(obj)
  File "c:\users\samuel\microblog4\venv\lib\site-packages\sqlalchemy\orm\relationships.py", line 1820, in entity
    argument = self.argument()
  File "c:\users\samuel\microblog4\venv\lib\site-packages\sqlalchemy\ext\declarative\clsregistry.py", line 306, in __call__
    % (self.prop.parent, self.arg, n.args[0], self.cls)
sqlalchemy.exc.InvalidRequestError: When initializing mapper mapped class Users->users, expression 'User' failed to locate a name ("name 'User' is not defined"). If this is a class name, consider adding this relationship() to the <class 'app.models.Users'> class after both dependent classes have been defined.
2019-07-22 16:46:44,764 ERROR: Exception on /favicon.ico [GET] [in c:\users\samuel\microblog4\venv\lib\site-packages\flask\app.py:1761]
Traceback (most recent call last):
  File "c:\users\samuel\microblog4\venv\lib\site-packages\flask\app.py", line 2292, in wsgi_app
    response = self.full_dispatch_request()
  File "c:\users\samuel\microblog4\venv\lib\site-packages\flask\app.py", line 1815, in full_dispatch_request
    rv = self.handle_user_exception(e)
  File "c:\users\samuel\microblog4\venv\lib\site-packages\flask\app.py", line 1718, in handle_user_exception
    reraise(exc_type, exc_value, tb)
  File "c:\users\samuel\microblog4\venv\lib\site-packages\flask\_compat.py", line 35, in reraise
    raise value
  File "c:\users\samuel\microblog4\venv\lib\site-packages\flask\app.py", line 1811, in full_dispatch_request
    rv = self.preprocess_request()
  File "c:\users\samuel\microblog4\venv\lib\site-packages\flask\app.py", line 2087, in preprocess_request
    rv = func()
  File "C:\Users\Samuel\microblog4\app\routes.py", line 14, in before_request
    if current_user.is_authenticated:
  File "c:\users\samuel\microblog4\venv\lib\site-packages\werkzeug\local.py", line 348, in __getattr__
    return getattr(self._get_current_object(), name)
  File "c:\users\samuel\microblog4\venv\lib\site-packages\werkzeug\local.py", line 307, in _get_current_object
    return self.__local()
  File "c:\users\samuel\microblog4\venv\lib\site-packages\flask_login\utils.py", line 26, in <lambda>
    current_user = LocalProxy(lambda: _get_user())
  File "c:\users\samuel\microblog4\venv\lib\site-packages\flask_login\utils.py", line 335, in _get_user
    current_app.login_manager._load_user()
  File "c:\users\samuel\microblog4\venv\lib\site-packages\flask_login\login_manager.py", line 359, in _load_user
    return self.reload_user()
  File "c:\users\samuel\microblog4\venv\lib\site-packages\flask_login\login_manager.py", line 321, in reload_user
    user = self.user_callback(user_id)
  File "C:\Users\Samuel\microblog4\app\models.py", line 81, in load_user
    return Users.query.get(int(id))
  File "c:\users\samuel\microblog4\venv\lib\site-packages\flask_sqlalchemy\__init__.py", line 512, in __get__
    mapper = orm.class_mapper(type)
  File "c:\users\samuel\microblog4\venv\lib\site-packages\sqlalchemy\orm\base.py", line 441, in class_mapper
    mapper = _inspect_mapped_class(class_, configure=configure)
  File "c:\users\samuel\microblog4\venv\lib\site-packages\sqlalchemy\orm\base.py", line 420, in _inspect_mapped_class
    mapper._configure_all()
  File "c:\users\samuel\microblog4\venv\lib\site-packages\sqlalchemy\orm\mapper.py", line 1337, in _configure_all
    configure_mappers()
  File "c:\users\samuel\microblog4\venv\lib\site-packages\sqlalchemy\orm\mapper.py", line 3225, in configure_mappers
    raise e
sqlalchemy.exc.InvalidRequestError: One or more mappers failed to initialize - can't proceed with initialization of other mappers. Triggering mapper: 'mapped class Users->users'. Original exception was: When initializing mapper mapped class Users->users, expression 'User' failed to locate a name ("name 'User' is not defined"). If this is a class name, consider adding this relationship() to the <class 'app.models.Users'> class after both dependent classes have been defined.
2019-07-22 16:48:16,538 INFO: Microblog startup [in C:\Users\Samuel\microblog4\app\__init__.py:53]
2019-07-22 16:48:45,949 INFO: Microblog startup [in C:\Users\Samuel\microblog4\app\__init__.py:53]
2019-07-22 16:49:32,233 INFO: Microblog startup [in C:\Users\Samuel\microblog4\app\__init__.py:53]
2019-07-22 16:50:57,356 INFO: Microblog startup [in C:\Users\Samuel\microblog4\app\__init__.py:53]
2019-07-22 16:53:19,081 INFO: Microblog startup [in C:\Users\Samuel\microblog4\app\__init__.py:53]
